[2024-10-16T20:00:17.756+0000] {taskinstance.py:1037} DEBUG - previous_execution_date was called
[2024-10-16T20:00:17.780+0000] {__init__.py:51} DEBUG - Loading core task runner: StandardTaskRunner
[2024-10-16T20:00:17.795+0000] {taskinstance.py:1037} DEBUG - previous_execution_date was called
[2024-10-16T20:00:17.802+0000] {base_task_runner.py:68} DEBUG - Planning to run as the  user
[2024-10-16T20:00:17.805+0000] {taskinstance.py:789} DEBUG - Refreshing TaskInstance <TaskInstance: btcusdt_data_ingestion.ingest_btcusdt manual__2024-10-16T20:00:12.557541+00:00 [queued]> from DB
[2024-10-16T20:00:17.824+0000] {taskinstance.py:1112} DEBUG - <TaskInstance: btcusdt_data_ingestion.ingest_btcusdt manual__2024-10-16T20:00:12.557541+00:00 [queued]> dependency 'Task Instance State' PASSED: True, Task state queued was valid.
[2024-10-16T20:00:17.825+0000] {taskinstance.py:1112} DEBUG - <TaskInstance: btcusdt_data_ingestion.ingest_btcusdt manual__2024-10-16T20:00:12.557541+00:00 [queued]> dependency 'Previous Dagrun State' PASSED: True, The task did not have depends_on_past set.
[2024-10-16T20:00:17.825+0000] {taskinstance.py:1112} DEBUG - <TaskInstance: btcusdt_data_ingestion.ingest_btcusdt manual__2024-10-16T20:00:12.557541+00:00 [queued]> dependency 'Task Instance Not Running' PASSED: True, Task is not in running state.
[2024-10-16T20:00:17.833+0000] {taskinstance.py:1112} DEBUG - <TaskInstance: btcusdt_data_ingestion.ingest_btcusdt manual__2024-10-16T20:00:12.557541+00:00 [queued]> dependency 'Not In Retry Period' PASSED: True, The task instance was not marked for retrying.
[2024-10-16T20:00:17.833+0000] {taskinstance.py:1103} INFO - Dependencies all met for dep_context=non-requeueable deps ti=<TaskInstance: btcusdt_data_ingestion.ingest_btcusdt manual__2024-10-16T20:00:12.557541+00:00 [queued]>
[2024-10-16T20:00:17.834+0000] {taskinstance.py:1112} DEBUG - <TaskInstance: btcusdt_data_ingestion.ingest_btcusdt manual__2024-10-16T20:00:12.557541+00:00 [queued]> dependency 'Task Concurrency' PASSED: True, Task concurrency is not set.
[2024-10-16T20:00:17.834+0000] {taskinstance.py:1112} DEBUG - <TaskInstance: btcusdt_data_ingestion.ingest_btcusdt manual__2024-10-16T20:00:12.557541+00:00 [queued]> dependency 'Previous Dagrun State' PASSED: True, The task did not have depends_on_past set.
[2024-10-16T20:00:17.838+0000] {taskinstance.py:1112} DEBUG - <TaskInstance: btcusdt_data_ingestion.ingest_btcusdt manual__2024-10-16T20:00:12.557541+00:00 [queued]> dependency 'Not In Retry Period' PASSED: True, The task instance was not marked for retrying.
[2024-10-16T20:00:17.843+0000] {taskinstance.py:1112} DEBUG - <TaskInstance: btcusdt_data_ingestion.ingest_btcusdt manual__2024-10-16T20:00:12.557541+00:00 [queued]> dependency 'Pool Slots Available' PASSED: True, There are enough open slots in default_pool to execute the task
[2024-10-16T20:00:17.843+0000] {taskinstance.py:1103} INFO - Dependencies all met for dep_context=requeueable deps ti=<TaskInstance: btcusdt_data_ingestion.ingest_btcusdt manual__2024-10-16T20:00:12.557541+00:00 [queued]>
[2024-10-16T20:00:17.844+0000] {taskinstance.py:1308} INFO - Starting attempt 1 of 2
[2024-10-16T20:00:17.857+0000] {taskinstance.py:1327} INFO - Executing <Task(PythonOperator): ingest_btcusdt> on 2024-10-16 20:00:12.557541+00:00
[2024-10-16T20:00:17.861+0000] {standard_task_runner.py:57} INFO - Started process 3256 to run task
[2024-10-16T20:00:17.865+0000] {standard_task_runner.py:84} INFO - Running: ['airflow', 'tasks', 'run', 'btcusdt_data_ingestion', 'ingest_btcusdt', 'manual__2024-10-16T20:00:12.557541+00:00', '--job-id', '114', '--raw', '--subdir', 'DAGS_FOLDER/ingest_btcusdt_data.py', '--cfg-path', '/tmp/tmpt03vz1q4']
[2024-10-16T20:00:17.868+0000] {standard_task_runner.py:85} INFO - Job 114: Subtask ingest_btcusdt
[2024-10-16T20:00:17.869+0000] {cli_action_loggers.py:65} DEBUG - Calling callbacks: [<function default_action_log at 0x7f7ca9505550>]
[2024-10-16T20:00:17.924+0000] {taskinstance.py:1037} DEBUG - previous_execution_date was called
[2024-10-16T20:00:17.932+0000] {task_command.py:410} INFO - Running <TaskInstance: btcusdt_data_ingestion.ingest_btcusdt manual__2024-10-16T20:00:12.557541+00:00 [running]> on host 888d2c584607
[2024-10-16T20:00:17.933+0000] {settings.py:353} DEBUG - Disposing DB connection pool (PID 3256)
[2024-10-16T20:00:17.933+0000] {settings.py:212} DEBUG - Setting up DB connection pool (PID 3256)
[2024-10-16T20:00:17.933+0000] {settings.py:285} DEBUG - settings.prepare_engine_args(): Using NullPool
[2024-10-16T20:00:17.935+0000] {taskinstance.py:789} DEBUG - Refreshing TaskInstance <TaskInstance: btcusdt_data_ingestion.ingest_btcusdt manual__2024-10-16T20:00:12.557541+00:00 [running]> from DB
[2024-10-16T20:00:17.977+0000] {taskinstance.py:1037} DEBUG - previous_execution_date was called
[2024-10-16T20:00:17.986+0000] {taskinstance.py:868} DEBUG - Clearing XCom data
[2024-10-16T20:00:18.021+0000] {retries.py:80} DEBUG - Running RenderedTaskInstanceFields._do_delete_old_records with retries. Try 1 of 3
[2024-10-16T20:00:18.036+0000] {taskinstance.py:1545} INFO - Exporting env vars: AIRFLOW_CTX_DAG_OWNER='airflow' AIRFLOW_CTX_DAG_ID='btcusdt_data_ingestion' AIRFLOW_CTX_TASK_ID='ingest_btcusdt' AIRFLOW_CTX_EXECUTION_DATE='2024-10-16T20:00:12.557541+00:00' AIRFLOW_CTX_TRY_NUMBER='1' AIRFLOW_CTX_DAG_RUN_ID='manual__2024-10-16T20:00:12.557541+00:00'
[2024-10-16T20:00:18.036+0000] {__init__.py:117} DEBUG - Preparing lineage inlets and outlets
[2024-10-16T20:00:18.037+0000] {__init__.py:155} DEBUG - inlets: [], outlets: []
[2024-10-16T20:00:18.045+0000] {base.py:73} INFO - Using connection ID 'company_dw' for task execution.
[2024-10-16T20:00:23.334+0000] {taskinstance.py:789} DEBUG - Refreshing TaskInstance <TaskInstance: btcusdt_data_ingestion.ingest_btcusdt manual__2024-10-16T20:00:12.557541+00:00 [running]> from DB
[2024-10-16T20:00:23.475+0000] {job.py:213} DEBUG - [heartbeat]
[2024-10-16T20:00:28.515+0000] {taskinstance.py:789} DEBUG - Refreshing TaskInstance <TaskInstance: btcusdt_data_ingestion.ingest_btcusdt manual__2024-10-16T20:00:12.557541+00:00 [running]> from DB
[2024-10-16T20:00:28.551+0000] {job.py:213} DEBUG - [heartbeat]
[2024-10-16T20:00:33.588+0000] {taskinstance.py:789} DEBUG - Refreshing TaskInstance <TaskInstance: btcusdt_data_ingestion.ingest_btcusdt manual__2024-10-16T20:00:12.557541+00:00 [running]> from DB
[2024-10-16T20:00:33.601+0000] {job.py:213} DEBUG - [heartbeat]
[2024-10-16T20:00:38.653+0000] {taskinstance.py:789} DEBUG - Refreshing TaskInstance <TaskInstance: btcusdt_data_ingestion.ingest_btcusdt manual__2024-10-16T20:00:12.557541+00:00 [running]> from DB
[2024-10-16T20:00:38.678+0000] {job.py:213} DEBUG - [heartbeat]
[2024-10-16T20:00:43.724+0000] {taskinstance.py:789} DEBUG - Refreshing TaskInstance <TaskInstance: btcusdt_data_ingestion.ingest_btcusdt manual__2024-10-16T20:00:12.557541+00:00 [running]> from DB
[2024-10-16T20:00:43.805+0000] {job.py:213} DEBUG - [heartbeat]
[2024-10-16T20:00:48.868+0000] {taskinstance.py:789} DEBUG - Refreshing TaskInstance <TaskInstance: btcusdt_data_ingestion.ingest_btcusdt manual__2024-10-16T20:00:12.557541+00:00 [running]> from DB
[2024-10-16T20:00:48.897+0000] {job.py:213} DEBUG - [heartbeat]
[2024-10-16T20:00:53.941+0000] {taskinstance.py:789} DEBUG - Refreshing TaskInstance <TaskInstance: btcusdt_data_ingestion.ingest_btcusdt manual__2024-10-16T20:00:12.557541+00:00 [running]> from DB
[2024-10-16T20:00:53.954+0000] {job.py:213} DEBUG - [heartbeat]
[2024-10-16T20:00:58.973+0000] {taskinstance.py:789} DEBUG - Refreshing TaskInstance <TaskInstance: btcusdt_data_ingestion.ingest_btcusdt manual__2024-10-16T20:00:12.557541+00:00 [running]> from DB
[2024-10-16T20:00:59.001+0000] {job.py:213} DEBUG - [heartbeat]
[2024-10-16T20:01:04.090+0000] {taskinstance.py:789} DEBUG - Refreshing TaskInstance <TaskInstance: btcusdt_data_ingestion.ingest_btcusdt manual__2024-10-16T20:00:12.557541+00:00 [running]> from DB
[2024-10-16T20:01:04.120+0000] {job.py:213} DEBUG - [heartbeat]
[2024-10-16T20:01:09.145+0000] {taskinstance.py:789} DEBUG - Refreshing TaskInstance <TaskInstance: btcusdt_data_ingestion.ingest_btcusdt manual__2024-10-16T20:00:12.557541+00:00 [running]> from DB
[2024-10-16T20:01:09.162+0000] {job.py:213} DEBUG - [heartbeat]
[2024-10-16T20:01:14.218+0000] {taskinstance.py:789} DEBUG - Refreshing TaskInstance <TaskInstance: btcusdt_data_ingestion.ingest_btcusdt manual__2024-10-16T20:00:12.557541+00:00 [running]> from DB
[2024-10-16T20:01:14.244+0000] {job.py:213} DEBUG - [heartbeat]
[2024-10-16T20:01:19.294+0000] {taskinstance.py:789} DEBUG - Refreshing TaskInstance <TaskInstance: btcusdt_data_ingestion.ingest_btcusdt manual__2024-10-16T20:00:12.557541+00:00 [running]> from DB
[2024-10-16T20:01:19.320+0000] {job.py:213} DEBUG - [heartbeat]
[2024-10-16T20:01:24.360+0000] {taskinstance.py:789} DEBUG - Refreshing TaskInstance <TaskInstance: btcusdt_data_ingestion.ingest_btcusdt manual__2024-10-16T20:00:12.557541+00:00 [running]> from DB
[2024-10-16T20:01:24.378+0000] {job.py:213} DEBUG - [heartbeat]
[2024-10-16T20:01:29.526+0000] {taskinstance.py:789} DEBUG - Refreshing TaskInstance <TaskInstance: btcusdt_data_ingestion.ingest_btcusdt manual__2024-10-16T20:00:12.557541+00:00 [running]> from DB
[2024-10-16T20:01:29.575+0000] {job.py:213} DEBUG - [heartbeat]
[2024-10-16T20:01:34.619+0000] {taskinstance.py:789} DEBUG - Refreshing TaskInstance <TaskInstance: btcusdt_data_ingestion.ingest_btcusdt manual__2024-10-16T20:00:12.557541+00:00 [running]> from DB
[2024-10-16T20:01:34.633+0000] {job.py:213} DEBUG - [heartbeat]
[2024-10-16T20:01:39.664+0000] {taskinstance.py:789} DEBUG - Refreshing TaskInstance <TaskInstance: btcusdt_data_ingestion.ingest_btcusdt manual__2024-10-16T20:00:12.557541+00:00 [running]> from DB
[2024-10-16T20:01:39.680+0000] {job.py:213} DEBUG - [heartbeat]
[2024-10-16T20:01:44.719+0000] {taskinstance.py:789} DEBUG - Refreshing TaskInstance <TaskInstance: btcusdt_data_ingestion.ingest_btcusdt manual__2024-10-16T20:00:12.557541+00:00 [running]> from DB
[2024-10-16T20:01:44.735+0000] {job.py:213} DEBUG - [heartbeat]
[2024-10-16T20:01:49.784+0000] {taskinstance.py:789} DEBUG - Refreshing TaskInstance <TaskInstance: btcusdt_data_ingestion.ingest_btcusdt manual__2024-10-16T20:00:12.557541+00:00 [running]> from DB
[2024-10-16T20:01:49.811+0000] {job.py:213} DEBUG - [heartbeat]
[2024-10-16T20:01:54.866+0000] {taskinstance.py:789} DEBUG - Refreshing TaskInstance <TaskInstance: btcusdt_data_ingestion.ingest_btcusdt manual__2024-10-16T20:00:12.557541+00:00 [running]> from DB
[2024-10-16T20:01:54.887+0000] {job.py:213} DEBUG - [heartbeat]
[2024-10-16T20:01:59.917+0000] {taskinstance.py:789} DEBUG - Refreshing TaskInstance <TaskInstance: btcusdt_data_ingestion.ingest_btcusdt manual__2024-10-16T20:00:12.557541+00:00 [running]> from DB
[2024-10-16T20:01:59.933+0000] {job.py:213} DEBUG - [heartbeat]
[2024-10-16T20:02:04.985+0000] {taskinstance.py:789} DEBUG - Refreshing TaskInstance <TaskInstance: btcusdt_data_ingestion.ingest_btcusdt manual__2024-10-16T20:00:12.557541+00:00 [running]> from DB
[2024-10-16T20:02:05.004+0000] {job.py:213} DEBUG - [heartbeat]
[2024-10-16T20:02:10.042+0000] {taskinstance.py:789} DEBUG - Refreshing TaskInstance <TaskInstance: btcusdt_data_ingestion.ingest_btcusdt manual__2024-10-16T20:00:12.557541+00:00 [running]> from DB
[2024-10-16T20:02:10.072+0000] {job.py:213} DEBUG - [heartbeat]
[2024-10-16T20:02:15.437+0000] {taskinstance.py:789} DEBUG - Refreshing TaskInstance <TaskInstance: btcusdt_data_ingestion.ingest_btcusdt manual__2024-10-16T20:00:12.557541+00:00 [running]> from DB
[2024-10-16T20:02:15.756+0000] {job.py:213} DEBUG - [heartbeat]
[2024-10-16T20:02:46.862+0000] {job.py:216} ERROR - Job heartbeat got an exception
Traceback (most recent call last):
  File "/home/airflow/.local/lib/python3.9/site-packages/sqlalchemy/engine/base.py", line 3366, in _wrap_pool_connect
    return fn()
  File "/home/airflow/.local/lib/python3.9/site-packages/sqlalchemy/pool/base.py", line 327, in connect
    return _ConnectionFairy._checkout(self)
  File "/home/airflow/.local/lib/python3.9/site-packages/sqlalchemy/pool/base.py", line 894, in _checkout
    fairy = _ConnectionRecord.checkout(pool)
  File "/home/airflow/.local/lib/python3.9/site-packages/sqlalchemy/pool/base.py", line 493, in checkout
    rec = pool._do_get()
  File "/home/airflow/.local/lib/python3.9/site-packages/sqlalchemy/pool/impl.py", line 256, in _do_get
    return self._create_connection()
  File "/home/airflow/.local/lib/python3.9/site-packages/sqlalchemy/pool/base.py", line 273, in _create_connection
    return _ConnectionRecord(self)
  File "/home/airflow/.local/lib/python3.9/site-packages/sqlalchemy/pool/base.py", line 388, in __init__
    self.__connect()
  File "/home/airflow/.local/lib/python3.9/site-packages/sqlalchemy/pool/base.py", line 691, in __connect
    pool.logger.debug("Error on connect(): %s", e)
  File "/home/airflow/.local/lib/python3.9/site-packages/sqlalchemy/util/langhelpers.py", line 70, in __exit__
    compat.raise_(
  File "/home/airflow/.local/lib/python3.9/site-packages/sqlalchemy/util/compat.py", line 211, in raise_
    raise exception
  File "/home/airflow/.local/lib/python3.9/site-packages/sqlalchemy/pool/base.py", line 686, in __connect
    self.dbapi_connection = connection = pool._invoke_creator(self)
  File "/home/airflow/.local/lib/python3.9/site-packages/sqlalchemy/engine/create.py", line 574, in connect
    return dialect.connect(*cargs, **cparams)
  File "/home/airflow/.local/lib/python3.9/site-packages/sqlalchemy/engine/default.py", line 598, in connect
    return self.dbapi.connect(*cargs, **cparams)
  File "/home/airflow/.local/lib/python3.9/site-packages/psycopg2/__init__.py", line 122, in connect
    conn = _connect(dsn, connection_factory=connection_factory, **kwasync)
psycopg2.OperationalError: could not translate host name "airflowdb" to address: Temporary failure in name resolution


The above exception was the direct cause of the following exception:

Traceback (most recent call last):
  File "/home/airflow/.local/lib/python3.9/site-packages/airflow/jobs/job.py", line 187, in heartbeat
    session.merge(self)
  File "/home/airflow/.local/lib/python3.9/site-packages/sqlalchemy/orm/session.py", line 3056, in merge
    return self._merge(
  File "/home/airflow/.local/lib/python3.9/site-packages/sqlalchemy/orm/session.py", line 3136, in _merge
    merged = self.get(
  File "/home/airflow/.local/lib/python3.9/site-packages/sqlalchemy/orm/session.py", line 2853, in get
    return self._get_impl(
  File "/home/airflow/.local/lib/python3.9/site-packages/sqlalchemy/orm/session.py", line 2975, in _get_impl
    return db_load_fn(
  File "/home/airflow/.local/lib/python3.9/site-packages/sqlalchemy/orm/loading.py", line 530, in load_on_pk_identity
    session.execute(
  File "/home/airflow/.local/lib/python3.9/site-packages/sqlalchemy/orm/session.py", line 1716, in execute
    conn = self._connection_for_bind(bind)
  File "/home/airflow/.local/lib/python3.9/site-packages/sqlalchemy/orm/session.py", line 1555, in _connection_for_bind
    return self._transaction._connection_for_bind(
  File "/home/airflow/.local/lib/python3.9/site-packages/sqlalchemy/orm/session.py", line 750, in _connection_for_bind
    conn = bind.connect()
  File "/home/airflow/.local/lib/python3.9/site-packages/sqlalchemy/engine/base.py", line 3320, in connect
    return self._connection_cls(self, close_with_result=close_with_result)
  File "/home/airflow/.local/lib/python3.9/site-packages/sqlalchemy/engine/base.py", line 96, in __init__
    else engine.raw_connection()
  File "/home/airflow/.local/lib/python3.9/site-packages/sqlalchemy/engine/base.py", line 3399, in raw_connection
    return self._wrap_pool_connect(self.pool.connect, _connection)
  File "/home/airflow/.local/lib/python3.9/site-packages/sqlalchemy/engine/base.py", line 3369, in _wrap_pool_connect
    Connection._handle_dbapi_exception_noconnection(
  File "/home/airflow/.local/lib/python3.9/site-packages/sqlalchemy/engine/base.py", line 2203, in _handle_dbapi_exception_noconnection
    util.raise_(
  File "/home/airflow/.local/lib/python3.9/site-packages/sqlalchemy/util/compat.py", line 211, in raise_
    raise exception
  File "/home/airflow/.local/lib/python3.9/site-packages/sqlalchemy/engine/base.py", line 3366, in _wrap_pool_connect
    return fn()
  File "/home/airflow/.local/lib/python3.9/site-packages/sqlalchemy/pool/base.py", line 327, in connect
    return _ConnectionFairy._checkout(self)
  File "/home/airflow/.local/lib/python3.9/site-packages/sqlalchemy/pool/base.py", line 894, in _checkout
    fairy = _ConnectionRecord.checkout(pool)
  File "/home/airflow/.local/lib/python3.9/site-packages/sqlalchemy/pool/base.py", line 493, in checkout
    rec = pool._do_get()
  File "/home/airflow/.local/lib/python3.9/site-packages/sqlalchemy/pool/impl.py", line 256, in _do_get
    return self._create_connection()
  File "/home/airflow/.local/lib/python3.9/site-packages/sqlalchemy/pool/base.py", line 273, in _create_connection
    return _ConnectionRecord(self)
  File "/home/airflow/.local/lib/python3.9/site-packages/sqlalchemy/pool/base.py", line 388, in __init__
    self.__connect()
  File "/home/airflow/.local/lib/python3.9/site-packages/sqlalchemy/pool/base.py", line 691, in __connect
    pool.logger.debug("Error on connect(): %s", e)
  File "/home/airflow/.local/lib/python3.9/site-packages/sqlalchemy/util/langhelpers.py", line 70, in __exit__
    compat.raise_(
  File "/home/airflow/.local/lib/python3.9/site-packages/sqlalchemy/util/compat.py", line 211, in raise_
    raise exception
  File "/home/airflow/.local/lib/python3.9/site-packages/sqlalchemy/pool/base.py", line 686, in __connect
    self.dbapi_connection = connection = pool._invoke_creator(self)
  File "/home/airflow/.local/lib/python3.9/site-packages/sqlalchemy/engine/create.py", line 574, in connect
    return dialect.connect(*cargs, **cparams)
  File "/home/airflow/.local/lib/python3.9/site-packages/sqlalchemy/engine/default.py", line 598, in connect
    return self.dbapi.connect(*cargs, **cparams)
  File "/home/airflow/.local/lib/python3.9/site-packages/psycopg2/__init__.py", line 122, in connect
    conn = _connect(dsn, connection_factory=connection_factory, **kwasync)
sqlalchemy.exc.OperationalError: (psycopg2.OperationalError) could not translate host name "airflowdb" to address: Temporary failure in name resolution

(Background on this error at: https://sqlalche.me/e/14/e3q8)
[2024-10-16T20:05:21.474+0000] {job.py:216} ERROR - Job heartbeat got an exception
Traceback (most recent call last):
  File "/home/airflow/.local/lib/python3.9/site-packages/sqlalchemy/engine/base.py", line 3366, in _wrap_pool_connect
    return fn()
  File "/home/airflow/.local/lib/python3.9/site-packages/sqlalchemy/pool/base.py", line 327, in connect
    return _ConnectionFairy._checkout(self)
  File "/home/airflow/.local/lib/python3.9/site-packages/sqlalchemy/pool/base.py", line 894, in _checkout
    fairy = _ConnectionRecord.checkout(pool)
  File "/home/airflow/.local/lib/python3.9/site-packages/sqlalchemy/pool/base.py", line 493, in checkout
    rec = pool._do_get()
  File "/home/airflow/.local/lib/python3.9/site-packages/sqlalchemy/pool/impl.py", line 256, in _do_get
    return self._create_connection()
  File "/home/airflow/.local/lib/python3.9/site-packages/sqlalchemy/pool/base.py", line 273, in _create_connection
    return _ConnectionRecord(self)
  File "/home/airflow/.local/lib/python3.9/site-packages/sqlalchemy/pool/base.py", line 388, in __init__
    self.__connect()
  File "/home/airflow/.local/lib/python3.9/site-packages/sqlalchemy/pool/base.py", line 691, in __connect
    pool.logger.debug("Error on connect(): %s", e)
  File "/home/airflow/.local/lib/python3.9/site-packages/sqlalchemy/util/langhelpers.py", line 70, in __exit__
    compat.raise_(
  File "/home/airflow/.local/lib/python3.9/site-packages/sqlalchemy/util/compat.py", line 211, in raise_
    raise exception
  File "/home/airflow/.local/lib/python3.9/site-packages/sqlalchemy/pool/base.py", line 686, in __connect
    self.dbapi_connection = connection = pool._invoke_creator(self)
  File "/home/airflow/.local/lib/python3.9/site-packages/sqlalchemy/engine/create.py", line 574, in connect
    return dialect.connect(*cargs, **cparams)
  File "/home/airflow/.local/lib/python3.9/site-packages/sqlalchemy/engine/default.py", line 598, in connect
    return self.dbapi.connect(*cargs, **cparams)
  File "/home/airflow/.local/lib/python3.9/site-packages/psycopg2/__init__.py", line 122, in connect
    conn = _connect(dsn, connection_factory=connection_factory, **kwasync)
psycopg2.OperationalError: could not translate host name "airflowdb" to address: Temporary failure in name resolution


The above exception was the direct cause of the following exception:

Traceback (most recent call last):
  File "/home/airflow/.local/lib/python3.9/site-packages/airflow/jobs/job.py", line 187, in heartbeat
    session.merge(self)
  File "/home/airflow/.local/lib/python3.9/site-packages/sqlalchemy/orm/session.py", line 3056, in merge
    return self._merge(
  File "/home/airflow/.local/lib/python3.9/site-packages/sqlalchemy/orm/session.py", line 3136, in _merge
    merged = self.get(
  File "/home/airflow/.local/lib/python3.9/site-packages/sqlalchemy/orm/session.py", line 2853, in get
    return self._get_impl(
  File "/home/airflow/.local/lib/python3.9/site-packages/sqlalchemy/orm/session.py", line 2975, in _get_impl
    return db_load_fn(
  File "/home/airflow/.local/lib/python3.9/site-packages/sqlalchemy/orm/loading.py", line 530, in load_on_pk_identity
    session.execute(
  File "/home/airflow/.local/lib/python3.9/site-packages/sqlalchemy/orm/session.py", line 1716, in execute
    conn = self._connection_for_bind(bind)
  File "/home/airflow/.local/lib/python3.9/site-packages/sqlalchemy/orm/session.py", line 1555, in _connection_for_bind
    return self._transaction._connection_for_bind(
  File "/home/airflow/.local/lib/python3.9/site-packages/sqlalchemy/orm/session.py", line 750, in _connection_for_bind
    conn = bind.connect()
  File "/home/airflow/.local/lib/python3.9/site-packages/sqlalchemy/engine/base.py", line 3320, in connect
    return self._connection_cls(self, close_with_result=close_with_result)
  File "/home/airflow/.local/lib/python3.9/site-packages/sqlalchemy/engine/base.py", line 96, in __init__
    else engine.raw_connection()
  File "/home/airflow/.local/lib/python3.9/site-packages/sqlalchemy/engine/base.py", line 3399, in raw_connection
    return self._wrap_pool_connect(self.pool.connect, _connection)
  File "/home/airflow/.local/lib/python3.9/site-packages/sqlalchemy/engine/base.py", line 3369, in _wrap_pool_connect
    Connection._handle_dbapi_exception_noconnection(
  File "/home/airflow/.local/lib/python3.9/site-packages/sqlalchemy/engine/base.py", line 2203, in _handle_dbapi_exception_noconnection
    util.raise_(
  File "/home/airflow/.local/lib/python3.9/site-packages/sqlalchemy/util/compat.py", line 211, in raise_
    raise exception
  File "/home/airflow/.local/lib/python3.9/site-packages/sqlalchemy/engine/base.py", line 3366, in _wrap_pool_connect
    return fn()
  File "/home/airflow/.local/lib/python3.9/site-packages/sqlalchemy/pool/base.py", line 327, in connect
    return _ConnectionFairy._checkout(self)
  File "/home/airflow/.local/lib/python3.9/site-packages/sqlalchemy/pool/base.py", line 894, in _checkout
    fairy = _ConnectionRecord.checkout(pool)
  File "/home/airflow/.local/lib/python3.9/site-packages/sqlalchemy/pool/base.py", line 493, in checkout
    rec = pool._do_get()
  File "/home/airflow/.local/lib/python3.9/site-packages/sqlalchemy/pool/impl.py", line 256, in _do_get
    return self._create_connection()
  File "/home/airflow/.local/lib/python3.9/site-packages/sqlalchemy/pool/base.py", line 273, in _create_connection
    return _ConnectionRecord(self)
  File "/home/airflow/.local/lib/python3.9/site-packages/sqlalchemy/pool/base.py", line 388, in __init__
    self.__connect()
  File "/home/airflow/.local/lib/python3.9/site-packages/sqlalchemy/pool/base.py", line 691, in __connect
    pool.logger.debug("Error on connect(): %s", e)
  File "/home/airflow/.local/lib/python3.9/site-packages/sqlalchemy/util/langhelpers.py", line 70, in __exit__
    compat.raise_(
  File "/home/airflow/.local/lib/python3.9/site-packages/sqlalchemy/util/compat.py", line 211, in raise_
    raise exception
  File "/home/airflow/.local/lib/python3.9/site-packages/sqlalchemy/pool/base.py", line 686, in __connect
    self.dbapi_connection = connection = pool._invoke_creator(self)
  File "/home/airflow/.local/lib/python3.9/site-packages/sqlalchemy/engine/create.py", line 574, in connect
    return dialect.connect(*cargs, **cparams)
  File "/home/airflow/.local/lib/python3.9/site-packages/sqlalchemy/engine/default.py", line 598, in connect
    return self.dbapi.connect(*cargs, **cparams)
  File "/home/airflow/.local/lib/python3.9/site-packages/psycopg2/__init__.py", line 122, in connect
    conn = _connect(dsn, connection_factory=connection_factory, **kwasync)
sqlalchemy.exc.OperationalError: (psycopg2.OperationalError) could not translate host name "airflowdb" to address: Temporary failure in name resolution

(Background on this error at: https://sqlalche.me/e/14/e3q8)
[2024-10-16T20:07:10.354+0000] {taskinstance.py:789} DEBUG - Refreshing TaskInstance <TaskInstance: btcusdt_data_ingestion.ingest_btcusdt manual__2024-10-16T20:00:12.557541+00:00 [running]> from DB
[2024-10-16T20:07:10.427+0000] {job.py:213} DEBUG - [heartbeat]
[2024-10-16T20:07:15.679+0000] {taskinstance.py:789} DEBUG - Refreshing TaskInstance <TaskInstance: btcusdt_data_ingestion.ingest_btcusdt manual__2024-10-16T20:00:12.557541+00:00 [running]> from DB
[2024-10-16T20:07:16.080+0000] {job.py:213} DEBUG - [heartbeat]
[2024-10-16T20:07:59.417+0000] {job.py:216} ERROR - Job heartbeat got an exception
Traceback (most recent call last):
  File "/home/airflow/.local/lib/python3.9/site-packages/sqlalchemy/engine/base.py", line 3366, in _wrap_pool_connect
    return fn()
  File "/home/airflow/.local/lib/python3.9/site-packages/sqlalchemy/pool/base.py", line 327, in connect
    return _ConnectionFairy._checkout(self)
  File "/home/airflow/.local/lib/python3.9/site-packages/sqlalchemy/pool/base.py", line 894, in _checkout
    fairy = _ConnectionRecord.checkout(pool)
  File "/home/airflow/.local/lib/python3.9/site-packages/sqlalchemy/pool/base.py", line 493, in checkout
    rec = pool._do_get()
  File "/home/airflow/.local/lib/python3.9/site-packages/sqlalchemy/pool/impl.py", line 256, in _do_get
    return self._create_connection()
  File "/home/airflow/.local/lib/python3.9/site-packages/sqlalchemy/pool/base.py", line 273, in _create_connection
    return _ConnectionRecord(self)
  File "/home/airflow/.local/lib/python3.9/site-packages/sqlalchemy/pool/base.py", line 388, in __init__
    self.__connect()
  File "/home/airflow/.local/lib/python3.9/site-packages/sqlalchemy/pool/base.py", line 691, in __connect
    pool.logger.debug("Error on connect(): %s", e)
  File "/home/airflow/.local/lib/python3.9/site-packages/sqlalchemy/util/langhelpers.py", line 70, in __exit__
    compat.raise_(
  File "/home/airflow/.local/lib/python3.9/site-packages/sqlalchemy/util/compat.py", line 211, in raise_
    raise exception
  File "/home/airflow/.local/lib/python3.9/site-packages/sqlalchemy/pool/base.py", line 686, in __connect
    self.dbapi_connection = connection = pool._invoke_creator(self)
  File "/home/airflow/.local/lib/python3.9/site-packages/sqlalchemy/engine/create.py", line 574, in connect
    return dialect.connect(*cargs, **cparams)
  File "/home/airflow/.local/lib/python3.9/site-packages/sqlalchemy/engine/default.py", line 598, in connect
    return self.dbapi.connect(*cargs, **cparams)
  File "/home/airflow/.local/lib/python3.9/site-packages/psycopg2/__init__.py", line 122, in connect
    conn = _connect(dsn, connection_factory=connection_factory, **kwasync)
psycopg2.OperationalError: could not translate host name "airflowdb" to address: Temporary failure in name resolution


The above exception was the direct cause of the following exception:

Traceback (most recent call last):
  File "/home/airflow/.local/lib/python3.9/site-packages/airflow/jobs/job.py", line 187, in heartbeat
    session.merge(self)
  File "/home/airflow/.local/lib/python3.9/site-packages/sqlalchemy/orm/session.py", line 3056, in merge
    return self._merge(
  File "/home/airflow/.local/lib/python3.9/site-packages/sqlalchemy/orm/session.py", line 3136, in _merge
    merged = self.get(
  File "/home/airflow/.local/lib/python3.9/site-packages/sqlalchemy/orm/session.py", line 2853, in get
    return self._get_impl(
  File "/home/airflow/.local/lib/python3.9/site-packages/sqlalchemy/orm/session.py", line 2975, in _get_impl
    return db_load_fn(
  File "/home/airflow/.local/lib/python3.9/site-packages/sqlalchemy/orm/loading.py", line 530, in load_on_pk_identity
    session.execute(
  File "/home/airflow/.local/lib/python3.9/site-packages/sqlalchemy/orm/session.py", line 1716, in execute
    conn = self._connection_for_bind(bind)
  File "/home/airflow/.local/lib/python3.9/site-packages/sqlalchemy/orm/session.py", line 1555, in _connection_for_bind
    return self._transaction._connection_for_bind(
  File "/home/airflow/.local/lib/python3.9/site-packages/sqlalchemy/orm/session.py", line 750, in _connection_for_bind
    conn = bind.connect()
  File "/home/airflow/.local/lib/python3.9/site-packages/sqlalchemy/engine/base.py", line 3320, in connect
    return self._connection_cls(self, close_with_result=close_with_result)
  File "/home/airflow/.local/lib/python3.9/site-packages/sqlalchemy/engine/base.py", line 96, in __init__
    else engine.raw_connection()
  File "/home/airflow/.local/lib/python3.9/site-packages/sqlalchemy/engine/base.py", line 3399, in raw_connection
    return self._wrap_pool_connect(self.pool.connect, _connection)
  File "/home/airflow/.local/lib/python3.9/site-packages/sqlalchemy/engine/base.py", line 3369, in _wrap_pool_connect
    Connection._handle_dbapi_exception_noconnection(
  File "/home/airflow/.local/lib/python3.9/site-packages/sqlalchemy/engine/base.py", line 2203, in _handle_dbapi_exception_noconnection
    util.raise_(
  File "/home/airflow/.local/lib/python3.9/site-packages/sqlalchemy/util/compat.py", line 211, in raise_
    raise exception
  File "/home/airflow/.local/lib/python3.9/site-packages/sqlalchemy/engine/base.py", line 3366, in _wrap_pool_connect
    return fn()
  File "/home/airflow/.local/lib/python3.9/site-packages/sqlalchemy/pool/base.py", line 327, in connect
    return _ConnectionFairy._checkout(self)
  File "/home/airflow/.local/lib/python3.9/site-packages/sqlalchemy/pool/base.py", line 894, in _checkout
    fairy = _ConnectionRecord.checkout(pool)
  File "/home/airflow/.local/lib/python3.9/site-packages/sqlalchemy/pool/base.py", line 493, in checkout
    rec = pool._do_get()
  File "/home/airflow/.local/lib/python3.9/site-packages/sqlalchemy/pool/impl.py", line 256, in _do_get
    return self._create_connection()
  File "/home/airflow/.local/lib/python3.9/site-packages/sqlalchemy/pool/base.py", line 273, in _create_connection
    return _ConnectionRecord(self)
  File "/home/airflow/.local/lib/python3.9/site-packages/sqlalchemy/pool/base.py", line 388, in __init__
    self.__connect()
  File "/home/airflow/.local/lib/python3.9/site-packages/sqlalchemy/pool/base.py", line 691, in __connect
    pool.logger.debug("Error on connect(): %s", e)
  File "/home/airflow/.local/lib/python3.9/site-packages/sqlalchemy/util/langhelpers.py", line 70, in __exit__
    compat.raise_(
  File "/home/airflow/.local/lib/python3.9/site-packages/sqlalchemy/util/compat.py", line 211, in raise_
    raise exception
  File "/home/airflow/.local/lib/python3.9/site-packages/sqlalchemy/pool/base.py", line 686, in __connect
    self.dbapi_connection = connection = pool._invoke_creator(self)
  File "/home/airflow/.local/lib/python3.9/site-packages/sqlalchemy/engine/create.py", line 574, in connect
    return dialect.connect(*cargs, **cparams)
  File "/home/airflow/.local/lib/python3.9/site-packages/sqlalchemy/engine/default.py", line 598, in connect
    return self.dbapi.connect(*cargs, **cparams)
  File "/home/airflow/.local/lib/python3.9/site-packages/psycopg2/__init__.py", line 122, in connect
    conn = _connect(dsn, connection_factory=connection_factory, **kwasync)
sqlalchemy.exc.OperationalError: (psycopg2.OperationalError) could not translate host name "airflowdb" to address: Temporary failure in name resolution

(Background on this error at: https://sqlalche.me/e/14/e3q8)
[2024-10-16T20:09:54.428+0000] {taskinstance.py:789} DEBUG - Refreshing TaskInstance <TaskInstance: btcusdt_data_ingestion.ingest_btcusdt manual__2024-10-16T20:00:12.557541+00:00 [running]> from DB
[2024-10-16T20:09:54.544+0000] {job.py:213} DEBUG - [heartbeat]
[2024-10-16T20:09:55.374+0000] {local_task_job_runner.py:225} INFO - Task exited with return code Negsignal.SIGKILL
[2024-10-16T20:09:56.087+0000] {dagrun.py:697} DEBUG - number of tis tasks for <DagRun btcusdt_data_ingestion @ 2024-10-16 20:00:12.557541+00:00: manual__2024-10-16T20:00:12.557541+00:00, state:running, queued_at: 2024-10-16 20:00:12.566038+00:00. externally triggered: True>: 0 task(s)
[2024-10-16T20:09:56.102+0000] {taskinstance.py:2651} INFO - 0 downstream tasks scheduled from follow-on schedule check
